User belongs to experiment group 'pythonaa'
User belongs to experiment group 'pythonJoinMailingListVar2'
User belongs to experiment group 'pythonJediLSP'
User belongs to experiment group 'pythonDiscoveryModuleWithoutWatcher'
User belongs to experiment group 'pythonTensorboardExperiment'
User belongs to experiment group 'PythonPyTorchProfiler'
User belongs to experiment group 'pythonDeprecatePythonPath'
User belongs to experiment group 'pythonSortEnvs'
User belongs to experiment group 'pythonRunFailedTestsButtonDisplayed'
User belongs to experiment group 'pythonRefreshTestsButtonDisplayedcf'
User belongs to experiment group 'pythonRememberDebugConfigcf'
Python interpreter path: /bin/python3
Starting Pylance language server.
Error 2021-09-13 19:46:18: Failed to check if file needs to be fixed [EntryNotFound (FileSystemError): Unable to read file 'vscode-remote://ssh-remote+104.211.21.197/home/bseddiqi3/.config/Code/User/settings.json' (Error: Unable to resolve non-existing file 'vscode-remote://ssh-remote+104.211.21.197/home/bseddiqi3/.config/Code/User/settings.json')
	at _handleError (/home/bseddiqi3/.vscode-server/bin/c3f126316369cd610563c75b1b1725e0679adfb3/out/vs/server/remoteExtensionHostProcess.js:84:167834)
	at async y.readText (/home/bseddiqi3/.vscode-server/extensions/ms-python.python-2021.8.1159798656/out/client/extension.js:9:320331)
	at async p.doesFileNeedToBeFixed (/home/bseddiqi3/.vscode-server/extensions/ms-python.python-2021.8.1159798656/out/client/extension.js:59:586718)
	at async /home/bseddiqi3/.vscode-server/extensions/ms-python.python-2021.8.1159798656/out/client/extension.js:59:585845
	at async Promise.all (index 0)
	at async p.getFilesToBeFixed (/home/bseddiqi3/.vscode-server/extensions/ms-python.python-2021.8.1159798656/out/client/extension.js:59:585791)
	at async p.updateTestSettings (/home/bseddiqi3/.vscode-server/extensions/ms-python.python-2021.8.1159798656/out/client/extension.js:59:585418)] {
  code: 'FileNotFound'
}
Error 2021-09-13 19:46:18: Failed to check if file needs to be fixed [EntryNotFound (FileSystemError): Unable to read file 'vscode-remote://ssh-remote+104.211.21.197/home/bseddiqi3/.vscode/settings.json' (Error: Unable to resolve non-existing file 'vscode-remote://ssh-remote+104.211.21.197/home/bseddiqi3/.vscode/settings.json')
	at _handleError (/home/bseddiqi3/.vscode-server/bin/c3f126316369cd610563c75b1b1725e0679adfb3/out/vs/server/remoteExtensionHostProcess.js:84:167834)
	at async y.readText (/home/bseddiqi3/.vscode-server/extensions/ms-python.python-2021.8.1159798656/out/client/extension.js:9:320331)
	at async p.doesFileNeedToBeFixed (/home/bseddiqi3/.vscode-server/extensions/ms-python.python-2021.8.1159798656/out/client/extension.js:59:586718)
	at async /home/bseddiqi3/.vscode-server/extensions/ms-python.python-2021.8.1159798656/out/client/extension.js:59:585845
	at async Promise.all (index 1)
	at async p.getFilesToBeFixed (/home/bseddiqi3/.vscode-server/extensions/ms-python.python-2021.8.1159798656/out/client/extension.js:59:585791)
	at async p.updateTestSettings (/home/bseddiqi3/.vscode-server/extensions/ms-python.python-2021.8.1159798656/out/client/extension.js:59:585418)] {
  code: 'FileNotFound'
}
> conda --version
Error 2021-09-13 19:58:57: Error while running worker[Worker 2]. undefined
Error 2021-09-13 19:58:57: Error while running worker[Worker 1]. undefined
Error 2021-09-13 19:58:57: Failed to prompt to launch TensorBoard session based on preexisting tfevent files in workspace: Canceled: Canceled
Error 2021-09-13 19:58:57: stat() failed for "/home/bseddiqi3/.pylintrc" [Canceled (FileSystemError): Canceled
	at _handleError (/home/bseddiqi3/.vscode-server/bin/c3f126316369cd610563c75b1b1725e0679adfb3/out/vs/server/remoteExtensionHostProcess.js:84:168274)
	at processTicksAndRejections (internal/process/task_queues.js:93:5)
	at runNextTicks (internal/process/task_queues.js:62:3)
	at processTimers (internal/timers.js:494:9)
	at async b.pathExists (/home/bseddiqi3/.vscode-server/extensions/ms-python.python-2021.8.1159798656/out/client/extension.js:9:322197)
	at async f.isLinterAvailable (/home/bseddiqi3/.vscode-server/extensions/ms-python.python-2021.8.1159798656/out/client/extension.js:59:468820)
	at async f.promptIfLinterAvailable (/home/bseddiqi3/.vscode-server/extensions/ms-python.python-2021.8.1159798656/out/client/extension.js:59:467880)
	at async _.enableUnconfiguredLinters (/home/bseddiqi3/.vscode-server/extensions/ms-python.python-2021.8.1159798656/out/client/extension.js:59:472927)
	at async _.getActiveLinters (/home/bseddiqi3/.vscode-server/extensions/ms-python.python-2021.8.1159798656/out/client/extension.js:59:471501)
	at async _.isLintingEnabled (/home/bseddiqi3/.vscode-server/extensions/ms-python.python-2021.8.1159798656/out/client/extension.js:59:471301)
	at async _.shouldLintDocument (/home/bseddiqi3/.vscode-server/extensions/ms-python.python-2021.8.1159798656/out/client/extension.js:59:487442)
	at async _.lintDocument (/home/bseddiqi3/.vscode-server/extensions/ms-python.python-2021.8.1159798656/out/client/extension.js:59:485986)
	at async Promise.all (index 0)
	at async _.lintOpenPythonFiles (/home/bseddiqi3/.vscode-server/extensions/ms-python.python-2021.8.1159798656/out/client/extension.js:59:485841)] {
  code: 'Unknown'
}
Error 2021-09-13 19:58:57: stat() failed for "/home/bseddiqi3/.vscode/launch.json" [Canceled (FileSystemError): Canceled
	at _handleError (/home/bseddiqi3/.vscode-server/bin/c3f126316369cd610563c75b1b1725e0679adfb3/out/vs/server/remoteExtensionHostProcess.js:84:168274)
	at processTicksAndRejections (internal/process/task_queues.js:93:5)
	at runNextTicks (internal/process/task_queues.js:62:3)
	at processTimers (internal/timers.js:494:9)
	at async b.pathExists (/home/bseddiqi3/.vscode-server/extensions/ms-python.python-2021.8.1159798656/out/client/extension.js:9:322197)
	at async b.diagnoseWorkspace (/home/bseddiqi3/.vscode-server/extensions/ms-python.python-2021.8.1159798656/out/client/extension.js:59:259026)
	at async /home/bseddiqi3/.vscode-server/extensions/ms-python.python-2021.8.1159798656/out/client/extension.js:59:253793
	at async Promise.all (index 1)
	at async h.runDiagnostics (/home/bseddiqi3/.vscode-server/extensions/ms-python.python-2021.8.1159798656/out/client/extension.js:59:253751)] {
  code: 'Unknown'
}
Error 2021-09-13 19:58:57: stat() failed for "/home/bseddiqi3/pylintrc" [Canceled (FileSystemError): Canceled
	at _handleError (/home/bseddiqi3/.vscode-server/bin/c3f126316369cd610563c75b1b1725e0679adfb3/out/vs/server/remoteExtensionHostProcess.js:84:168274)
	at processTicksAndRejections (internal/process/task_queues.js:93:5)
	at runNextTicks (internal/process/task_queues.js:62:3)
	at processTimers (internal/timers.js:494:9)] {
  code: 'Unknown'
}
